[2025-04-13T23:35:00.550+0800] {local_task_job_runner.py:123} INFO - ::group::Pre task execution logs
[2025-04-13T23:35:00.558+0800] {taskinstance.py:2614} INFO - Dependencies all met for dep_context=non-requeueable deps ti=<TaskInstance: visitor_labels_etl_pipeline.load_to_mongodb manual__2025-04-13T15:34:52.727857+00:00 [queued]>
[2025-04-13T23:35:00.562+0800] {taskinstance.py:2614} INFO - Dependencies all met for dep_context=requeueable deps ti=<TaskInstance: visitor_labels_etl_pipeline.load_to_mongodb manual__2025-04-13T15:34:52.727857+00:00 [queued]>
[2025-04-13T23:35:00.562+0800] {taskinstance.py:2867} INFO - Starting attempt 1 of 2
[2025-04-13T23:35:00.573+0800] {taskinstance.py:2890} INFO - Executing <Task(PythonOperator): load_to_mongodb> on 2025-04-13 15:34:52.727857+00:00
[2025-04-13T23:35:00.576+0800] {standard_task_runner.py:72} INFO - Started process 90838 to run task
[2025-04-13T23:35:00.578+0800] {standard_task_runner.py:104} INFO - Running: ['airflow', 'tasks', 'run', 'visitor_labels_etl_pipeline', 'load_to_mongodb', 'manual__2025-04-13T15:34:52.727857+00:00', '--job-id', '49', '--raw', '--subdir', 'DAGS_FOLDER/labels_dag.py', '--cfg-path', '/tmp/tmp0ov9gnl6']
[2025-04-13T23:35:00.579+0800] {standard_task_runner.py:105} INFO - Job 49: Subtask load_to_mongodb
[2025-04-13T23:35:00.604+0800] {task_command.py:467} INFO - Running <TaskInstance: visitor_labels_etl_pipeline.load_to_mongodb manual__2025-04-13T15:34:52.727857+00:00 [running]> on host Conglaptop.
[2025-04-13T23:35:00.650+0800] {taskinstance.py:3134} INFO - Exporting env vars: AIRFLOW_CTX_DAG_OWNER='airflow' AIRFLOW_CTX_DAG_ID='visitor_labels_etl_pipeline' AIRFLOW_CTX_TASK_ID='load_to_mongodb' AIRFLOW_CTX_EXECUTION_DATE='2025-04-13T15:34:52.727857+00:00' AIRFLOW_CTX_TRY_NUMBER='1' AIRFLOW_CTX_DAG_RUN_ID='manual__2025-04-13T15:34:52.727857+00:00'
[2025-04-13T23:35:00.651+0800] {logging_mixin.py:190} INFO - Task instance is in running state
[2025-04-13T23:35:00.651+0800] {logging_mixin.py:190} INFO -  Previous state of the Task instance: queued
[2025-04-13T23:35:00.651+0800] {logging_mixin.py:190} INFO - Current task name:load_to_mongodb state:running start_date:2025-04-13 15:35:00.558749+00:00
[2025-04-13T23:35:00.651+0800] {logging_mixin.py:190} INFO - Dag name:visitor_labels_etl_pipeline and current dag run status:running
[2025-04-13T23:35:00.651+0800] {taskinstance.py:732} INFO - ::endgroup::
[2025-04-13T23:35:00.653+0800] {logging_mixin.py:190} INFO - Loading 10 visitor records to MongoDB
[2025-04-13T23:35:00.779+0800] {logging_mixin.py:190} INFO - Processing visitor data for period: 2025-03
[2025-04-13T23:35:00.779+0800] {logging_mixin.py:190} INFO - Error processing record: 'Collection' object is not callable. If you meant to call the 'update_one' method on a 'Database' object it is failing because no such method exists.
[2025-04-13T23:35:00.780+0800] {logging_mixin.py:190} INFO - Record: {'country': 'Thailand', 'month_year': '2025-03', 'value': 3300000.0}
[2025-04-13T23:35:00.780+0800] {logging_mixin.py:190} INFO - Error processing record: 'Collection' object is not callable. If you meant to call the 'update_one' method on a 'Database' object it is failing because no such method exists.
[2025-04-13T23:35:00.780+0800] {logging_mixin.py:190} INFO - Record: {'country': 'Singapore', 'month_year': '2025-03', 'value': 1743500.0}
[2025-04-13T23:35:00.780+0800] {logging_mixin.py:190} INFO - Error processing record: 'Collection' object is not callable. If you meant to call the 'update_one' method on a 'Database' object it is failing because no such method exists.
[2025-04-13T23:35:00.780+0800] {logging_mixin.py:190} INFO - Record: {'country': 'Malaysia', 'month_year': '2025-03', 'value': 2400000.0}
[2025-04-13T23:35:00.780+0800] {logging_mixin.py:190} INFO - Error processing record: 'Collection' object is not callable. If you meant to call the 'update_one' method on a 'Database' object it is failing because no such method exists.
[2025-04-13T23:35:00.780+0800] {logging_mixin.py:190} INFO - Record: {'country': 'Indonesia', 'month_year': '2025-03', 'value': 1150000.0}
[2025-04-13T23:35:00.780+0800] {logging_mixin.py:190} INFO - Error processing record: 'Collection' object is not callable. If you meant to call the 'update_one' method on a 'Database' object it is failing because no such method exists.
[2025-04-13T23:35:00.781+0800] {logging_mixin.py:190} INFO - Record: {'country': 'Vietnam', 'month_year': '2025-03', 'value': 1750000.0}
[2025-04-13T23:35:00.781+0800] {logging_mixin.py:190} INFO - Error processing record: 'Collection' object is not callable. If you meant to call the 'update_one' method on a 'Database' object it is failing because no such method exists.
[2025-04-13T23:35:00.781+0800] {logging_mixin.py:190} INFO - Record: {'country': 'Philippines', 'month_year': '2025-03', 'value': 530000.0}
[2025-04-13T23:35:00.781+0800] {logging_mixin.py:190} INFO - Error processing record: 'Collection' object is not callable. If you meant to call the 'update_one' method on a 'Database' object it is failing because no such method exists.
[2025-04-13T23:35:00.781+0800] {logging_mixin.py:190} INFO - Record: {'country': 'Cambodia', 'month_year': '2025-03', 'value': 635000.0}
[2025-04-13T23:35:00.781+0800] {logging_mixin.py:190} INFO - Error processing record: 'Collection' object is not callable. If you meant to call the 'update_one' method on a 'Database' object it is failing because no such method exists.
[2025-04-13T23:35:00.781+0800] {logging_mixin.py:190} INFO - Record: {'country': 'Laos', 'month_year': '2025-03', 'value': 470000.0}
[2025-04-13T23:35:00.781+0800] {logging_mixin.py:190} INFO - Error processing record: 'Collection' object is not callable. If you meant to call the 'update_one' method on a 'Database' object it is failing because no such method exists.
[2025-04-13T23:35:00.781+0800] {logging_mixin.py:190} INFO - Record: {'country': 'Myanmar', 'month_year': '2025-03', 'value': 124000.0}
[2025-04-13T23:35:00.782+0800] {logging_mixin.py:190} INFO - Error processing record: 'Collection' object is not callable. If you meant to call the 'update_one' method on a 'Database' object it is failing because no such method exists.
[2025-04-13T23:35:00.782+0800] {logging_mixin.py:190} INFO - Record: {'country': 'Brunei', 'month_year': '2025-03', 'value': 63578.0}
[2025-04-13T23:35:00.782+0800] {logging_mixin.py:190} INFO - Error during MongoDB operations: 'Collection' object is not callable. If you meant to call the 'count_documents' method on a 'Database' object it is failing because no such method exists.
[2025-04-13T23:35:00.782+0800] {taskinstance.py:3313} ERROR - Task failed with exception
Traceback (most recent call last):
  File "/home/rencongchia/Y3S2/BT4301/project/.venv/lib/python3.12/site-packages/airflow/models/taskinstance.py", line 768, in _execute_task
    result = _execute_callable(context=context, **execute_callable_kwargs)
             ^^^^^^^^^^^^^^^^^^^^^^^^^^^^^^^^^^^^^^^^^^^^^^^^^^^^^^^^^^^^^
  File "/home/rencongchia/Y3S2/BT4301/project/.venv/lib/python3.12/site-packages/airflow/models/taskinstance.py", line 734, in _execute_callable
    return ExecutionCallableRunner(
           ^^^^^^^^^^^^^^^^^^^^^^^^
  File "/home/rencongchia/Y3S2/BT4301/project/.venv/lib/python3.12/site-packages/airflow/utils/operator_helpers.py", line 252, in run
    return self.func(*args, **kwargs)
           ^^^^^^^^^^^^^^^^^^^^^^^^^^
  File "/home/rencongchia/Y3S2/BT4301/project/.venv/lib/python3.12/site-packages/airflow/models/baseoperator.py", line 424, in wrapper
    return func(self, *args, **kwargs)
           ^^^^^^^^^^^^^^^^^^^^^^^^^^^
  File "/home/rencongchia/Y3S2/BT4301/project/.venv/lib/python3.12/site-packages/airflow/operators/python.py", line 238, in execute
    return_value = self.execute_callable()
                   ^^^^^^^^^^^^^^^^^^^^^^^
  File "/home/rencongchia/Y3S2/BT4301/project/.venv/lib/python3.12/site-packages/airflow/operators/python.py", line 256, in execute_callable
    return runner.run(*self.op_args, **self.op_kwargs)
           ^^^^^^^^^^^^^^^^^^^^^^^^^^^^^^^^^^^^^^^^^^^
  File "/home/rencongchia/Y3S2/BT4301/project/.venv/lib/python3.12/site-packages/airflow/utils/operator_helpers.py", line 252, in run
    return self.func(*args, **kwargs)
           ^^^^^^^^^^^^^^^^^^^^^^^^^^
  File "/home/rencongchia/Y3S2/BT4301/project/airflow/dags/labels_dag.py", line 213, in load_to_mongodb
    verification_count = visitor_collection.count_documents({
                         ^^^^^^^^^^^^^^^^^^^^^^^^^^^^^^^^^^^^
  File "/home/rencongchia/Y3S2/BT4301/project/.venv/lib/python3.12/site-packages/pymongo/synchronous/collection.py", line 422, in __call__
    raise TypeError(
TypeError: 'Collection' object is not callable. If you meant to call the 'count_documents' method on a 'Database' object it is failing because no such method exists.
[2025-04-13T23:35:00.791+0800] {logging_mixin.py:190} INFO - Task instance in failure state
[2025-04-13T23:35:00.791+0800] {logging_mixin.py:190} INFO - Task start:2025-04-13 15:35:00.558749+00:00 end:2025-04-13 15:35:00.790344+00:00 duration:0.231595
[2025-04-13T23:35:00.792+0800] {logging_mixin.py:190} INFO - Task:<Task(PythonOperator): load_to_mongodb> dag:<DAG: visitor_labels_etl_pipeline> dagrun:<DagRun visitor_labels_etl_pipeline @ 2025-04-13 15:34:52.727857+00:00: manual__2025-04-13T15:34:52.727857+00:00, state:running, queued_at: 2025-04-13 15:34:52.741294+00:00. externally triggered: True>
[2025-04-13T23:35:00.792+0800] {logging_mixin.py:190} INFO - Failure caused by 'Collection' object is not callable. If you meant to call the 'count_documents' method on a 'Database' object it is failing because no such method exists.
[2025-04-13T23:35:00.792+0800] {taskinstance.py:1226} INFO - Marking task as UP_FOR_RETRY. dag_id=visitor_labels_etl_pipeline, task_id=load_to_mongodb, run_id=manual__2025-04-13T15:34:52.727857+00:00, execution_date=20250413T153452, start_date=20250413T153500, end_date=20250413T153500
[2025-04-13T23:35:00.813+0800] {taskinstance.py:341} INFO - ::group::Post task execution logs
[2025-04-13T23:35:00.814+0800] {standard_task_runner.py:124} ERROR - Failed to execute job 49 for task load_to_mongodb ('Collection' object is not callable. If you meant to call the 'count_documents' method on a 'Database' object it is failing because no such method exists.; 90838)
Traceback (most recent call last):
  File "/home/rencongchia/Y3S2/BT4301/project/.venv/lib/python3.12/site-packages/airflow/task/task_runner/standard_task_runner.py", line 117, in _start_by_fork
    ret = args.func(args, dag=self.dag)
          ^^^^^^^^^^^^^^^^^^^^^^^^^^^^^
  File "/home/rencongchia/Y3S2/BT4301/project/.venv/lib/python3.12/site-packages/airflow/cli/cli_config.py", line 49, in command
    return func(*args, **kwargs)
           ^^^^^^^^^^^^^^^^^^^^^
  File "/home/rencongchia/Y3S2/BT4301/project/.venv/lib/python3.12/site-packages/airflow/utils/cli.py", line 116, in wrapper
    return f(*args, **kwargs)
           ^^^^^^^^^^^^^^^^^^
  File "/home/rencongchia/Y3S2/BT4301/project/.venv/lib/python3.12/site-packages/airflow/cli/commands/task_command.py", line 483, in task_run
    task_return_code = _run_task_by_selected_method(args, _dag, ti)
                       ^^^^^^^^^^^^^^^^^^^^^^^^^^^^^^^^^^^^^^^^^^^^
  File "/home/rencongchia/Y3S2/BT4301/project/.venv/lib/python3.12/site-packages/airflow/cli/commands/task_command.py", line 256, in _run_task_by_selected_method
    return _run_raw_task(args, ti)
           ^^^^^^^^^^^^^^^^^^^^^^^
  File "/home/rencongchia/Y3S2/BT4301/project/.venv/lib/python3.12/site-packages/airflow/cli/commands/task_command.py", line 341, in _run_raw_task
    return ti._run_raw_task(
           ^^^^^^^^^^^^^^^^^
  File "/home/rencongchia/Y3S2/BT4301/project/.venv/lib/python3.12/site-packages/airflow/utils/session.py", line 97, in wrapper
    return func(*args, session=session, **kwargs)
           ^^^^^^^^^^^^^^^^^^^^^^^^^^^^^^^^^^^^^^
  File "/home/rencongchia/Y3S2/BT4301/project/.venv/lib/python3.12/site-packages/airflow/models/taskinstance.py", line 3006, in _run_raw_task
    return _run_raw_task(
           ^^^^^^^^^^^^^^
  File "/home/rencongchia/Y3S2/BT4301/project/.venv/lib/python3.12/site-packages/airflow/models/taskinstance.py", line 274, in _run_raw_task
    TaskInstance._execute_task_with_callbacks(
  File "/home/rencongchia/Y3S2/BT4301/project/.venv/lib/python3.12/site-packages/airflow/models/taskinstance.py", line 3161, in _execute_task_with_callbacks
    result = self._execute_task(context, task_orig)
             ^^^^^^^^^^^^^^^^^^^^^^^^^^^^^^^^^^^^^^
  File "/home/rencongchia/Y3S2/BT4301/project/.venv/lib/python3.12/site-packages/airflow/models/taskinstance.py", line 3185, in _execute_task
    return _execute_task(self, context, task_orig)
           ^^^^^^^^^^^^^^^^^^^^^^^^^^^^^^^^^^^^^^^
  File "/home/rencongchia/Y3S2/BT4301/project/.venv/lib/python3.12/site-packages/airflow/models/taskinstance.py", line 768, in _execute_task
    result = _execute_callable(context=context, **execute_callable_kwargs)
             ^^^^^^^^^^^^^^^^^^^^^^^^^^^^^^^^^^^^^^^^^^^^^^^^^^^^^^^^^^^^^
  File "/home/rencongchia/Y3S2/BT4301/project/.venv/lib/python3.12/site-packages/airflow/models/taskinstance.py", line 734, in _execute_callable
    return ExecutionCallableRunner(
           ^^^^^^^^^^^^^^^^^^^^^^^^
  File "/home/rencongchia/Y3S2/BT4301/project/.venv/lib/python3.12/site-packages/airflow/utils/operator_helpers.py", line 252, in run
    return self.func(*args, **kwargs)
           ^^^^^^^^^^^^^^^^^^^^^^^^^^
  File "/home/rencongchia/Y3S2/BT4301/project/.venv/lib/python3.12/site-packages/airflow/models/baseoperator.py", line 424, in wrapper
    return func(self, *args, **kwargs)
           ^^^^^^^^^^^^^^^^^^^^^^^^^^^
  File "/home/rencongchia/Y3S2/BT4301/project/.venv/lib/python3.12/site-packages/airflow/operators/python.py", line 238, in execute
    return_value = self.execute_callable()
                   ^^^^^^^^^^^^^^^^^^^^^^^
  File "/home/rencongchia/Y3S2/BT4301/project/.venv/lib/python3.12/site-packages/airflow/operators/python.py", line 256, in execute_callable
    return runner.run(*self.op_args, **self.op_kwargs)
           ^^^^^^^^^^^^^^^^^^^^^^^^^^^^^^^^^^^^^^^^^^^
  File "/home/rencongchia/Y3S2/BT4301/project/.venv/lib/python3.12/site-packages/airflow/utils/operator_helpers.py", line 252, in run
    return self.func(*args, **kwargs)
           ^^^^^^^^^^^^^^^^^^^^^^^^^^
  File "/home/rencongchia/Y3S2/BT4301/project/airflow/dags/labels_dag.py", line 213, in load_to_mongodb
    verification_count = visitor_collection.count_documents({
                         ^^^^^^^^^^^^^^^^^^^^^^^^^^^^^^^^^^^^
  File "/home/rencongchia/Y3S2/BT4301/project/.venv/lib/python3.12/site-packages/pymongo/synchronous/collection.py", line 422, in __call__
    raise TypeError(
TypeError: 'Collection' object is not callable. If you meant to call the 'count_documents' method on a 'Database' object it is failing because no such method exists.
[2025-04-13T23:35:00.832+0800] {local_task_job_runner.py:266} INFO - Task exited with return code 1
[2025-04-13T23:35:00.839+0800] {taskinstance.py:3901} INFO - 0 downstream tasks scheduled from follow-on schedule check
[2025-04-13T23:35:00.840+0800] {local_task_job_runner.py:245} INFO - ::endgroup::
