[2025-04-13T22:21:30.818+0800] {local_task_job_runner.py:123} INFO - ::group::Pre task execution logs
[2025-04-13T22:21:30.824+0800] {taskinstance.py:2614} INFO - Dependencies all met for dep_context=non-requeueable deps ti=<TaskInstance: instagram_etl_pipeline.extract_instagram_data manual__2025-04-13T14:21:27.579541+00:00 [queued]>
[2025-04-13T22:21:30.827+0800] {taskinstance.py:2614} INFO - Dependencies all met for dep_context=requeueable deps ti=<TaskInstance: instagram_etl_pipeline.extract_instagram_data manual__2025-04-13T14:21:27.579541+00:00 [queued]>
[2025-04-13T22:21:30.827+0800] {taskinstance.py:2867} INFO - Starting attempt 1 of 2
[2025-04-13T22:21:30.839+0800] {taskinstance.py:2890} INFO - Executing <Task(PythonOperator): extract_instagram_data> on 2025-04-13 14:21:27.579541+00:00
[2025-04-13T22:21:30.843+0800] {standard_task_runner.py:72} INFO - Started process 68852 to run task
[2025-04-13T22:21:30.844+0800] {standard_task_runner.py:104} INFO - Running: ['airflow', 'tasks', 'run', 'instagram_etl_pipeline', 'extract_instagram_data', 'manual__2025-04-13T14:21:27.579541+00:00', '--job-id', '21', '--raw', '--subdir', 'DAGS_FOLDER/instagram_dag.py', '--cfg-path', '/tmp/tmp6sd_b9ix']
[2025-04-13T22:21:30.845+0800] {standard_task_runner.py:105} INFO - Job 21: Subtask extract_instagram_data
[2025-04-13T22:21:30.876+0800] {task_command.py:467} INFO - Running <TaskInstance: instagram_etl_pipeline.extract_instagram_data manual__2025-04-13T14:21:27.579541+00:00 [running]> on host Conglaptop.
[2025-04-13T22:21:30.918+0800] {taskinstance.py:3134} INFO - Exporting env vars: AIRFLOW_CTX_DAG_OWNER='airflow' AIRFLOW_CTX_DAG_ID='instagram_etl_pipeline' AIRFLOW_CTX_TASK_ID='extract_instagram_data' AIRFLOW_CTX_EXECUTION_DATE='2025-04-13T14:21:27.579541+00:00' AIRFLOW_CTX_TRY_NUMBER='1' AIRFLOW_CTX_DAG_RUN_ID='manual__2025-04-13T14:21:27.579541+00:00'
[2025-04-13T22:21:30.919+0800] {logging_mixin.py:190} INFO - Task instance is in running state
[2025-04-13T22:21:30.919+0800] {logging_mixin.py:190} INFO -  Previous state of the Task instance: queued
[2025-04-13T22:21:30.920+0800] {logging_mixin.py:190} INFO - Current task name:extract_instagram_data state:running start_date:2025-04-13 14:21:30.824549+00:00
[2025-04-13T22:21:30.920+0800] {logging_mixin.py:190} INFO - Dag name:instagram_etl_pipeline and current dag run status:running
[2025-04-13T22:21:30.920+0800] {taskinstance.py:732} INFO - ::endgroup::
[2025-04-13T22:21:31.922+0800] {private.py:328} INFO - https://i.instagram.com/api/v1/feed/timeline/
[2025-04-13T22:21:31.994+0800] {logging_mixin.py:190} WARNING - /home/rencongchia/Y3S2/BT4301/project/.venv/lib/python3.12/site-packages/urllib3/connectionpool.py:1097 InsecureRequestWarning: Unverified HTTPS request is being made to host 'i.instagram.com'. Adding certificate verification is strongly advised. See: https://urllib3.readthedocs.io/en/latest/advanced-usage.html#tls-warnings
[2025-04-13T22:21:34.602+0800] {private.py:484} INFO - bt_grp_8_2025 [200] POST https://i.instagram.com/api/v1/feed/timeline/ (269.0.0.18.75, OnePlus 6T Dev)
[2025-04-13T22:21:34.605+0800] {instagram_crawler.py:67} INFO - successfully logged in via session
[2025-04-13T22:21:34.606+0800] {logging_mixin.py:190} INFO - Error during Instagram data extraction: [Errno 2] No such file or directory: '/home/rencongchia/Y3S2/BT4301/project/backend/data/city_posts.json'
[2025-04-13T22:21:34.606+0800] {taskinstance.py:3313} ERROR - Task failed with exception
Traceback (most recent call last):
  File "/home/rencongchia/Y3S2/BT4301/project/.venv/lib/python3.12/site-packages/airflow/models/taskinstance.py", line 768, in _execute_task
    result = _execute_callable(context=context, **execute_callable_kwargs)
             ^^^^^^^^^^^^^^^^^^^^^^^^^^^^^^^^^^^^^^^^^^^^^^^^^^^^^^^^^^^^^
  File "/home/rencongchia/Y3S2/BT4301/project/.venv/lib/python3.12/site-packages/airflow/models/taskinstance.py", line 734, in _execute_callable
    return ExecutionCallableRunner(
           ^^^^^^^^^^^^^^^^^^^^^^^^
  File "/home/rencongchia/Y3S2/BT4301/project/.venv/lib/python3.12/site-packages/airflow/utils/operator_helpers.py", line 252, in run
    return self.func(*args, **kwargs)
           ^^^^^^^^^^^^^^^^^^^^^^^^^^
  File "/home/rencongchia/Y3S2/BT4301/project/.venv/lib/python3.12/site-packages/airflow/models/baseoperator.py", line 424, in wrapper
    return func(self, *args, **kwargs)
           ^^^^^^^^^^^^^^^^^^^^^^^^^^^
  File "/home/rencongchia/Y3S2/BT4301/project/.venv/lib/python3.12/site-packages/airflow/operators/python.py", line 238, in execute
    return_value = self.execute_callable()
                   ^^^^^^^^^^^^^^^^^^^^^^^
  File "/home/rencongchia/Y3S2/BT4301/project/.venv/lib/python3.12/site-packages/airflow/operators/python.py", line 256, in execute_callable
    return runner.run(*self.op_args, **self.op_kwargs)
           ^^^^^^^^^^^^^^^^^^^^^^^^^^^^^^^^^^^^^^^^^^^
  File "/home/rencongchia/Y3S2/BT4301/project/.venv/lib/python3.12/site-packages/airflow/utils/operator_helpers.py", line 252, in run
    return self.func(*args, **kwargs)
           ^^^^^^^^^^^^^^^^^^^^^^^^^^
  File "/home/rencongchia/Y3S2/BT4301/project/airflow/dags/instagram_dag.py", line 72, in extract_instagram_data
    crawler = InstagramCrawler(
              ^^^^^^^^^^^^^^^^^
  File "/home/rencongchia/Y3S2/BT4301/project/backend/src/instagram/instagram_crawler.py", line 44, in __init__
    with open(self.exisiting_city_posts_path, "r") as f:
         ^^^^^^^^^^^^^^^^^^^^^^^^^^^^^^^^^^^^^^^^^
FileNotFoundError: [Errno 2] No such file or directory: '/home/rencongchia/Y3S2/BT4301/project/backend/data/city_posts.json'
[2025-04-13T22:21:34.612+0800] {logging_mixin.py:190} INFO - Task instance in failure state
[2025-04-13T22:21:34.613+0800] {logging_mixin.py:190} INFO - Task start:2025-04-13 14:21:30.824549+00:00 end:2025-04-13 14:21:34.612555+00:00 duration:3.788006
[2025-04-13T22:21:34.613+0800] {logging_mixin.py:190} INFO - Task:<Task(PythonOperator): extract_instagram_data> dag:<DAG: instagram_etl_pipeline> dagrun:<DagRun instagram_etl_pipeline @ 2025-04-13 14:21:27.579541+00:00: manual__2025-04-13T14:21:27.579541+00:00, state:running, queued_at: 2025-04-13 14:21:27.601725+00:00. externally triggered: True>
[2025-04-13T22:21:34.613+0800] {logging_mixin.py:190} INFO - Failure caused by [Errno 2] No such file or directory: '/home/rencongchia/Y3S2/BT4301/project/backend/data/city_posts.json'
[2025-04-13T22:21:34.613+0800] {taskinstance.py:1226} INFO - Marking task as UP_FOR_RETRY. dag_id=instagram_etl_pipeline, task_id=extract_instagram_data, run_id=manual__2025-04-13T14:21:27.579541+00:00, execution_date=20250413T142127, start_date=20250413T142130, end_date=20250413T142134
[2025-04-13T22:21:34.638+0800] {taskinstance.py:341} INFO - ::group::Post task execution logs
[2025-04-13T22:21:34.639+0800] {standard_task_runner.py:124} ERROR - Failed to execute job 21 for task extract_instagram_data ([Errno 2] No such file or directory: '/home/rencongchia/Y3S2/BT4301/project/backend/data/city_posts.json'; 68852)
Traceback (most recent call last):
  File "/home/rencongchia/Y3S2/BT4301/project/.venv/lib/python3.12/site-packages/airflow/task/task_runner/standard_task_runner.py", line 117, in _start_by_fork
    ret = args.func(args, dag=self.dag)
          ^^^^^^^^^^^^^^^^^^^^^^^^^^^^^
  File "/home/rencongchia/Y3S2/BT4301/project/.venv/lib/python3.12/site-packages/airflow/cli/cli_config.py", line 49, in command
    return func(*args, **kwargs)
           ^^^^^^^^^^^^^^^^^^^^^
  File "/home/rencongchia/Y3S2/BT4301/project/.venv/lib/python3.12/site-packages/airflow/utils/cli.py", line 116, in wrapper
    return f(*args, **kwargs)
           ^^^^^^^^^^^^^^^^^^
  File "/home/rencongchia/Y3S2/BT4301/project/.venv/lib/python3.12/site-packages/airflow/cli/commands/task_command.py", line 483, in task_run
    task_return_code = _run_task_by_selected_method(args, _dag, ti)
                       ^^^^^^^^^^^^^^^^^^^^^^^^^^^^^^^^^^^^^^^^^^^^
  File "/home/rencongchia/Y3S2/BT4301/project/.venv/lib/python3.12/site-packages/airflow/cli/commands/task_command.py", line 256, in _run_task_by_selected_method
    return _run_raw_task(args, ti)
           ^^^^^^^^^^^^^^^^^^^^^^^
  File "/home/rencongchia/Y3S2/BT4301/project/.venv/lib/python3.12/site-packages/airflow/cli/commands/task_command.py", line 341, in _run_raw_task
    return ti._run_raw_task(
           ^^^^^^^^^^^^^^^^^
  File "/home/rencongchia/Y3S2/BT4301/project/.venv/lib/python3.12/site-packages/airflow/utils/session.py", line 97, in wrapper
    return func(*args, session=session, **kwargs)
           ^^^^^^^^^^^^^^^^^^^^^^^^^^^^^^^^^^^^^^
  File "/home/rencongchia/Y3S2/BT4301/project/.venv/lib/python3.12/site-packages/airflow/models/taskinstance.py", line 3006, in _run_raw_task
    return _run_raw_task(
           ^^^^^^^^^^^^^^
  File "/home/rencongchia/Y3S2/BT4301/project/.venv/lib/python3.12/site-packages/airflow/models/taskinstance.py", line 274, in _run_raw_task
    TaskInstance._execute_task_with_callbacks(
  File "/home/rencongchia/Y3S2/BT4301/project/.venv/lib/python3.12/site-packages/airflow/models/taskinstance.py", line 3161, in _execute_task_with_callbacks
    result = self._execute_task(context, task_orig)
             ^^^^^^^^^^^^^^^^^^^^^^^^^^^^^^^^^^^^^^
  File "/home/rencongchia/Y3S2/BT4301/project/.venv/lib/python3.12/site-packages/airflow/models/taskinstance.py", line 3185, in _execute_task
    return _execute_task(self, context, task_orig)
           ^^^^^^^^^^^^^^^^^^^^^^^^^^^^^^^^^^^^^^^
  File "/home/rencongchia/Y3S2/BT4301/project/.venv/lib/python3.12/site-packages/airflow/models/taskinstance.py", line 768, in _execute_task
    result = _execute_callable(context=context, **execute_callable_kwargs)
             ^^^^^^^^^^^^^^^^^^^^^^^^^^^^^^^^^^^^^^^^^^^^^^^^^^^^^^^^^^^^^
  File "/home/rencongchia/Y3S2/BT4301/project/.venv/lib/python3.12/site-packages/airflow/models/taskinstance.py", line 734, in _execute_callable
    return ExecutionCallableRunner(
           ^^^^^^^^^^^^^^^^^^^^^^^^
  File "/home/rencongchia/Y3S2/BT4301/project/.venv/lib/python3.12/site-packages/airflow/utils/operator_helpers.py", line 252, in run
    return self.func(*args, **kwargs)
           ^^^^^^^^^^^^^^^^^^^^^^^^^^
  File "/home/rencongchia/Y3S2/BT4301/project/.venv/lib/python3.12/site-packages/airflow/models/baseoperator.py", line 424, in wrapper
    return func(self, *args, **kwargs)
           ^^^^^^^^^^^^^^^^^^^^^^^^^^^
  File "/home/rencongchia/Y3S2/BT4301/project/.venv/lib/python3.12/site-packages/airflow/operators/python.py", line 238, in execute
    return_value = self.execute_callable()
                   ^^^^^^^^^^^^^^^^^^^^^^^
  File "/home/rencongchia/Y3S2/BT4301/project/.venv/lib/python3.12/site-packages/airflow/operators/python.py", line 256, in execute_callable
    return runner.run(*self.op_args, **self.op_kwargs)
           ^^^^^^^^^^^^^^^^^^^^^^^^^^^^^^^^^^^^^^^^^^^
  File "/home/rencongchia/Y3S2/BT4301/project/.venv/lib/python3.12/site-packages/airflow/utils/operator_helpers.py", line 252, in run
    return self.func(*args, **kwargs)
           ^^^^^^^^^^^^^^^^^^^^^^^^^^
  File "/home/rencongchia/Y3S2/BT4301/project/airflow/dags/instagram_dag.py", line 72, in extract_instagram_data
    crawler = InstagramCrawler(
              ^^^^^^^^^^^^^^^^^
  File "/home/rencongchia/Y3S2/BT4301/project/backend/src/instagram/instagram_crawler.py", line 44, in __init__
    with open(self.exisiting_city_posts_path, "r") as f:
         ^^^^^^^^^^^^^^^^^^^^^^^^^^^^^^^^^^^^^^^^^
FileNotFoundError: [Errno 2] No such file or directory: '/home/rencongchia/Y3S2/BT4301/project/backend/data/city_posts.json'
[2025-04-13T22:21:34.677+0800] {local_task_job_runner.py:266} INFO - Task exited with return code 1
[2025-04-13T22:21:34.687+0800] {taskinstance.py:3901} INFO - 0 downstream tasks scheduled from follow-on schedule check
[2025-04-13T22:21:34.688+0800] {local_task_job_runner.py:245} INFO - ::endgroup::
